Workbook

Sheet Cover
B2: Lumina Renewables S.p.A.: Monte Carlo DCF Valuation
B3: Alessandro Radice · fictional mid-market Italian solar and wind operator · educational project, not investment advice
B5: Sheet | E5: What it holds
B6: Assumptions | E6: Distributions of the six drivers, fixed parameters and the windfall-tax event (blue cells)
B7: DCF Base Case | E7: Five-year unlevered DCF at the most-likely value of every driver
B8: Simulation | E8: 2,000 live iterations: each row turns one set of random numbers into drivers and a value per share
B9: Random Draws | E9: The random numbers behind each row: the first 2,000 of the 50,000 in the Python run (seed 113)
B10: Results | E10: Mean, median, percentiles, probabilities and the histogram of the live iterations
B11: Sensitivity | E11: Which driver moves value most: live correlations and the 50,000-run rank correlations
B12: Windfall | E12: The tax risk modelled as an event that happens or not, on the same random numbers
B13: Convergence | E13: How much the median and the tails move between runs, from 250 to 50,000 iterations
B14: Price Paths | E14: Geometric Brownian Motion paths of the share price over five years
B15: Checks | E15: Every live iteration recomputed in Python and compared with Excel
B17: Colour code: blue = input, black = formula, green = link to another sheet.
B19: Headline results
B20: Value per share | C20: Live (2,000) | D20: Python (50,000) | E20: Note
B21: Base case (most-likely inputs) | C21: ='DCF Base Case'!C36 -> 14.916493 | D21: 14.916493 | E21: Single-point DCF
B22: Mean | C22: =Results!C6 -> 13.40285 | D22: 13.225795
B23: Median (P50) | C23: =Results!C7 -> 12.553903 | D23: 12.487061 | E23: The typical outcome
B24: Downside (P5) | C24: =Results!C9 -> 5.4605247 | D24: 5.3544624 | E24: One run in twenty is worse
B25: Upside (P95) | C25: =Results!C13 -> 24.176302 | D25: 23.61234 | E25: One run in twenty is better
B26: P(value > market price) | C26: =Results!C15 -> 0.58 | D26: 0.57478 | E26: Market price on the Assumptions sheet
B27: Base case above median | C27: =C21/C23-1 -> 0.18819564 | D27: 0.19455594 | E27: Why the point estimate flatters
B29: The live column moves with the blue inputs. The Python column is the 50,000-iteration headline and stays fixed; the two differ because 2,000 draws carry sampling noise (see Convergence).

Sheet Assumptions
B2: Assumptions
B3: Change any blue cell: the base case and all live iterations recalculate
B5: Driver | C5: Distribution | D5: Min / mean | E5: Mode / st. dev. | F5: Max | G5: Why
B6: Revenue growth (p.a.) | C6: Triangular | D6: 0.04 | E6: 0.09 | F6: 0.14 | G6: Contracted capacity plus new projects; skewed neither way
B7: EBITDA margin | C7: Triangular | D7: 0.36 | E7: 0.42 | F7: 0.46 | G7: Long tail down: curtailment, lower captured prices
B8: WACC | C8: Normal | D8: 0.085 | E8: 0.011 | G8: Capital-intensive and rate-sensitive; clipped to the floor and cap below
B9: Tax rate | C9: Triangular | D9: 0.24 | E9: 0.26 | F9: 0.35 | G9: IRES plus IRAP near 26%; tail to 35% for windfall-tax risk
B10: Terminal growth | C10: Triangular | D10: 0.01 | E10: 0.02 | F10: 0.0275 | G10: Around long-run inflation
B11: CapEx (% of revenue) | C11: Triangular | D11: 0.12 | E11: 0.16 | F11: 0.22 | G11: Repowering and grid costs can overrun
B13: Fixed parameters
B14: Base revenue (€m) | D14: 145
B15: D&A (% of revenue) | D15: 0.13
B16: Change in NWC (% of incremental revenue) | D16: 0.03
B17: Net debt (€m) | D17: 185
B18: Shares outstanding (m) | D18: 25
B19: Market price (€) | D19: 11.5
B20: Forecast horizon (years) | D20: 5
B21: Minimum WACC minus terminal growth | D21: 0.015
B22: Correlation, growth and margin (Gaussian copula) | D22: 0.35
B23: WACC floor | D23: 0.055
B24: WACC cap | D24: 0.125
B26: Windfall-tax event (Windfall sheet)
B27: Ordinary tax: min | D27: 0.24
B28: Ordinary tax: mode | D28: 0.26
B29: Ordinary tax: max | D29: 0.28
B30: Probability of a windfall surcharge | D30: 0.25 | G30: Illustrative; chosen so the average tax matches the continuous model
B31: Surcharge if it happens (points) | D31: 0.09
B33: Triangular: min, most likely, max. Normal: mean and standard deviation. The guardrail keeps WACC at least 1.5 points above terminal growth.

Sheet DCF Base Case
B2: DCF base case
B3: Every driver at its most-likely value (the mode, or the mean for WACC)
B6: Revenue growth | C6: =Assumptions!E6 -> 0.09
B7: EBITDA margin | C7: =Assumptions!E7 -> 0.42
B8: WACC | C8: =Assumptions!D8 -> 0.085
B9: Tax rate | C9: =Assumptions!E9 -> 0.26
B10: Terminal growth | C10: =Assumptions!E10 -> 0.02
B11: CapEx (% of revenue) | C11: =Assumptions!E11 -> 0.16
B12: Discount rate used | C12: =MAX(C8,C10+Assumptions!$D$21) -> 0.085
B14: €m | C14: Year 0 | D14: Y1 | E14: Y2 | F14: Y3 | G14: Y4 | H14: Y5
B15: Revenue | C15: =Assumptions!$D$14 -> 145 | D15: =C15*(1+$C$6) -> 158.05 | E15: =D15*(1+$C$6) -> 172.2745 | F15: =E15*(1+$C$6) -> 187.7792 | G15: =F15*(1+$C$6) -> 204.67933 | H15: =G15*(1+$C$6) -> 223.10047
B16: EBITDA | D16: =D15*$C$7 -> 66.381 | E16: =E15*$C$7 -> 72.35529 | F16: =F15*$C$7 -> 78.867266 | G16: =G15*$C$7 -> 85.96532 | H16: =H15*$C$7 -> 93.702199
B17: D&A | D17: =D15*Assumptions!$D$15 -> 20.5465 | E17: =E15*Assumptions!$D$15 -> 22.395685 | F17: =F15*Assumptions!$D$15 -> 24.411297 | G17: =G15*Assumptions!$D$15 -> 26.608313 | H17: =H15*Assumptions!$D$15 -> 29.003062
B18: EBIT | D18: =D16-D17 -> 45.8345 | E18: =E16-E17 -> 49.959605 | F18: =F16-F17 -> 54.455969 | G18: =G16-G17 -> 59.357007 | H18: =H16-H17 -> 64.699137
B19: NOPAT | D19: =D18*(1-$C$9) -> 33.91753 | E19: =E18*(1-$C$9) -> 36.970108 | F19: =F18*(1-$C$9) -> 40.297417 | G19: =G18*(1-$C$9) -> 43.924185 | H19: =H18*(1-$C$9) -> 47.877362
B20: CapEx | D20: =D15*$C$11 -> 25.288 | E20: =E15*$C$11 -> 27.56392 | F20: =F15*$C$11 -> 30.044673 | G20: =G15*$C$11 -> 32.748693 | H20: =H15*$C$11 -> 35.696076
B21: Change in NWC | D21: =(D15-C15)*Assumptions!$D$16 -> 0.3915 | E21: =(E15-D15)*Assumptions!$D$16 -> 0.426735 | F21: =(F15-E15)*Assumptions!$D$16 -> 0.46514115 | G21: =(G15-F15)*Assumptions!$D$16 -> 0.50700385 | H21: =(H15-G15)*Assumptions!$D$16 -> 0.5526342
B22: Unlevered free cash flow | D22: =D19+D17-D20-D21 -> 28.78453 | E22: =E19+E17-E20-E21 -> 31.375138 | F22: =F19+F17-F20-F21 -> 34.1989 | G22: =G19+G17-G20-G21 -> 37.276801 | H22: =H19+H17-H20-H21 -> 40.631713
B23: Discount factor | D23: =1/(1+$C$12)^1 -> 0.92165899 | E23: =1/(1+$C$12)^2 -> 0.84945529 | F23: =1/(1+$C$12)^3 -> 0.7829081 | G23: =1/(1+$C$12)^4 -> 0.72157428 | H23: =1/(1+$C$12)^5 -> 0.66504542
B24: Present value | D24: =D22*D23 -> 26.529521 | E24: =E22*E23 -> 26.651777 | F24: =F22*F23 -> 26.774596 | G24: =G22*G23 -> 26.897981 | H24: =H22*H23 -> 27.021935
B26: Sum of present values | C26: =SUM(D24:H24) -> 133.87581
B27: Terminal value (Gordon) | C27: =H22*(1+C10)/(C12-C10) -> 637.60535
B28: Present value of terminal value | C28: =C27/(1+C12)^5 -> 424.03652
B29: Enterprise value | C29: =C26+C28 -> 557.91233
B30: Net debt | C30: =Assumptions!$D$17 -> 185
B31: Equity value | C31: =C29-C30 -> 372.91233
B32: Shares (m) | C32: =Assumptions!$D$18 -> 25
B34: Terminal value share of enterprise value | C34: =C28/C29 -> 0.76004149
B36: Value per share (€) | C36: =C31/C32 -> 14.916493

Sheet Random Draws
B2: Random draws
B3: Standard normals (z) and uniforms (u) from the Python engine, seed 113, rows 1 to 2,000 of 50,000
B5: Iter | C5: z growth | D5: z margin (indep.) | E5: z WACC | F5: u tax | G5: u terminal g | H5: u CapEx | I5: u windfall
B6: 1 | C6: 1.5938667 | D6: 0.66741473 | E6: -0.66569892 | F6: 0.96032825 | G6: 0.24608927 | H6: 0.85581691 | I6: 0.72772361
B7: 2 | C7: 0.52756548 | D7: -0.42350392 | E7: -0.97035347 | F7: 0.88039948 | G7: 0.97649384 | H7: 0.67930698 | I7: 0.95724377
B8: 3 | C8: -0.059307457 | D8: 0.38865075 | E8: -0.27277407 | F8: 0.46577074 | G8: 0.094711251 | H8: 0.89231492 | I8: 0.64704779
B9: 4 | C9: -2.2364523 | D9: 0.48400101 | E9: -0.20052701 | F9: 0.71788869 | G9: 0.17558595 | H9: 0.03651515 | I9: 0.68641593
B10: 5 | C10: 0.98821484 | D10: -1.2107974 | E10: 1.4362515 | F10: 0.14144392 | G10: 0.23746365 | H10: 0.53866168 | I10: 0.21607571
B11: 6 | C11: 2.4534825 | D11: -0.59854802 | E11: 1.4931354 | F11: 0.92815365 | G11: 0.47008725 | H11: 0.98265317 | I11: 0.35160849
B12: 7 | C12: 2.4825237 | D12: -0.52045022 | E12: 0.12507058 | F12: 0.10597644 | G12: 0.70662838 | H12: 0.43212914 | I12: 0.29721096
B13: 8 | C13: 0.49980802 | D13: -0.11660245 | E13: -1.2874882 | F13: 0.74621545 | G13: 0.10611424 | H13: 0.29021183 | I13: 0.7002352
B14: 9 | C14: -0.61342849 | D14: -0.35513788 | E14: 0.081235047 | F14: 0.56515354 | G14: 0.27714404 | H14: 0.5224274 | I14: 0.71710503
B15: 10 | C15: 0.92703185 | D15: 0.35756745 | E15: -1.1195795 | F15: 0.42489974 | G15: 0.85305217 | H15: 0.78734497 | I15: 0.83664131
B16: 11 | C16: -2.0145937 | D16: -0.52222551 | E16: -0.56213198 | F16: 0.47262645 | G16: 0.09429933 | H16: 0.11556574 | I16: 0.67160368
B17: 12 | C17: -0.48320167 | D17: 2.0462954 | E17: -0.80151721 | F17: 0.16611014 | G17: 0.13601654 | H17: 0.25379696 | I17: 0.80012186
... B2005: 2000 | C2005: -0.94585254 | D2005: 2.1333136 | E2005: -1.402944 | F2005: 0.042543054 | G2005: 0.59244045 | H2005: 0.13611643 | I2005: 0.21981453

Sheet Simulation
B2: Simulation
B3: One iteration per row. Drivers come from the random draws through each distribution; the valuation is the base-case DCF
B5: Iter | C5: u growth | D5: u margin | E5: Growth | F5: Margin | G5: WACC | H5: Tax | I5: Terminal g | J5: CapEx % | K5: Rate used | L5: FCF per € rev. | M5: UFCF Y1 | N5: UFCF Y2 | O5: UFCF Y3 | P5: UFCF Y4 | Q5: UFCF Y5 | R5: PV explicit | S5: Terminal value | T5: Enterprise value | U5: Value per share
B6: 1 | C6: =NORMSDIST('Random Draws'!C6) -> 0.94451706 | D6: =NORMSDIST(Assumptions!$D$22*'Random Draws'!C6+SQRT(1-Assumptions!$D$22^2)*'Random Draws'!D6) -> 0.88160611 | E6: =IF(C6<(Assumptions!$E$6-Assumptions!$D$6)/(Assumptions!$F$6-Assumptions!$D$6),Assumptions!$D$6+SQRT(C6*(Assumptions!$F$6-Assumptions!$D$6)*(Assumptions!$E$6-Assumptions!$D$6)),Assumptions!$F$6-SQRT((1-C6)*(Assumptions!$F$6-Assumptions!$D$6)*(Assumptions!$F$6-Assumptions!$E$6))) -> 0.12334423 | F6: =IF(D6<(Assumptions!$E$7-Assumptions!$D$7)/(Assumptions!$F$7-Assumptions!$D$7),Assumptions!$D$7+SQRT(D6*(Assumptions!$F$7-Assumptions!$D$7)*(Assumptions!$E$7-Assumptions!$D$7)),Assumptions!$F$7-SQRT((1-D6)*(Assumptions!$F$7-Assumptions!$D$7)*(Assumptions!$F$7-Assumptions!$E$7))) -> 0.43823821 | G6: =MIN(Assumptions!$D$24,MAX(Assumptions!$D$23,Assumptions!$D$8+Assumptions!$E$8*'Random Draws'!E6)) -> 0.077677312 | H6: =IF('Random Draws'!F6<(Assumptions!$E$9-Assumptions!$D$9)/(Assumptions!$F$9-Assumptions!$D$9),Assumptions!$D$9+SQRT('Random Draws'!F6*(Assumptions!$F$9-Assumptions!$D$9)*(Assumptions!$E$9-Assumptions!$D$9)),Assumptions!$F$9-SQRT((1-'Random Draws'!F6)*(Assumptions!$F$9-Assumptions!$D$9)*(Assumptions!$F$9-Assumptions!$E$9))) -> 0.33018207 | I6: =IF('Random Draws'!G6<(Assumptions!$E$10-Assumptions!$D$10)/(Assumptions!$F$10-Assumptions!$D$10),Assumptions!$D$10+SQRT('Random Draws'!G6*(Assumptions!$F$10-Assumptions!$D$10)*(Assumptions!$E$10-Assumptions!$D$10)),Assumptions!$F$10-SQRT((1-'Random Draws'!G6)*(Assumptions!$F$10-Assumptions!$D$10)*(Assumptions!$F$10-Assumptions!$E$10))) -> 0.01656244 | J6: =IF('Random Draws'!H6<(Assumptions!$E$11-Assumptions!$D$11)/(Assumptions!$F$11-Assumptions!$D$11),Assumptions!$D$11+SQRT('Random Draws'!H6*(Assumptions!$F$11-Assumptions!$D$11)*(Assumptions!$E$11-Assumptions!$D$11)),Assumptions!$F$11-SQRT((1-'Random Draws'!H6)*(Assumptions!$F$11-Assumptions!$D$11)*(Assumptions!$F$11-Assumptions!$E$11))) -> 0.19058744 | K6: =MAX(G6,I6+Assumptions!$D$21) -> 0.077677312 | L6: =(F6-Assumptions!$D$15)*(1-H6)+Assumptions!$D$15-J6 -> 0.14587604 | M6: =Assumptions!$D$14*(1+E6)^1*L6-Assumptions!$D$14*(1+E6)^0*E6*Assumptions!$D$16 -> 23.224458 | N6: =Assumptions!$D$14*(1+E6)^2*L6-Assumptions!$D$14*(1+E6)^1*E6*Assumptions!$D$16 -> 26.089061 | O6: =Assumptions!$D$14*(1+E6)^3*L6-Assumptions!$D$14*(1+E6)^2*E6*Assumptions!$D$16 -> 29.306996 | P6: =Assumptions!$D$14*(1+E6)^4*L6-Assumptions!$D$14*(1+E6)^3*E6*Assumptions!$D$16 -> 32.921845 | Q6: =Assumptions!$D$14*(1+E6)^5*L6-Assumptions!$D$14*(1+E6)^4*E6*Assumptions!$D$16 -> 36.982565 | R6: =M6/(1+K6)+N6/(1+K6)^2+O6/(1+K6)^3+P6/(1+K6)^4+Q6/(1+K6)^5 -> 117.2797 | S6: =Q6*(1+I6)/(K6-I6) -> 615.15446 | T6: =R6+S6/(1+K6)^5 -> 540.47466 | U6: =(T6-Assumptions!$D$17)/Assumptions!$D$18 -> 14.218986
B7: 2 | C7: =NORMSDIST('Random Draws'!C7) -> 0.70109952 | D7: =NORMSDIST(Assumptions!$D$22*'Random Draws'!C7+SQRT(1-Assumptions!$D$22^2)*'Random Draws'!D7) -> 0.4160265 | E7: =IF(C7<(Assumptions!$E$6-Assumptions!$D$6)/(Assumptions!$F$6-Assumptions!$D$6),Assumptions!$D$6+SQRT(C7*(Assumptions!$F$6-Assumptions!$D$6)*(Assumptions!$E$6-Assumptions!$D$6)),Assumptions!$F$6-SQRT((1-C7)*(Assumptions!$F$6-Assumptions!$D$6)*(Assumptions!$F$6-Assumptions!$E$6))) -> 0.10134121 | F7: =IF(D7<(Assumptions!$E$7-Assumptions!$D$7)/(Assumptions!$F$7-Assumptions!$D$7),Assumptions!$D$7+SQRT(D7*(Assumptions!$F$7-Assumptions!$D$7)*(Assumptions!$E$7-Assumptions!$D$7)),Assumptions!$F$7-SQRT((1-D7)*(Assumptions!$F$7-Assumptions!$D$7)*(Assumptions!$F$7-Assumptions!$E$7))) -> 0.40996158 | G7: =MIN(Assumptions!$D$24,MAX(Assumptions!$D$23,Assumptions!$D$8+Assumptions!$E$8*'Random Draws'!E7)) -> 0.074326112 | H7: =IF('Random Draws'!F7<(Assumptions!$E$9-Assumptions!$D$9)/(Assumptions!$F$9-Assumptions!$D$9),Assumptions!$D$9+SQRT('Random Draws'!F7*(Assumptions!$F$9-Assumptions!$D$9)*(Assumptions!$E$9-Assumptions!$D$9)),Assumptions!$F$9-SQRT((1-'Random Draws'!F7)*(Assumptions!$F$9-Assumptions!$D$9)*(Assumptions!$F$9-Assumptions!$E$9))) -> 0.31559004 | I7: =IF('Random Draws'!G7<(Assumptions!$E$10-Assumptions!$D$10)/(Assumptions!$F$10-Assumptions!$D$10),Assumptions!$D$10+SQRT('Random Draws'!G7*(Assumptions!$F$10-Assumptions!$D$10)*(Assumptions!$E$10-Assumptions!$D$10)),Assumptions!$F$10-SQRT((1-'Random Draws'!G7)*(Assumptions!$F$10-Assumptions!$D$10)*(Assumptions!$F$10-Assumptions!$E$10))) -> 0.025743531 | J7: =IF('Random Draws'!H7<(Assumptions!$E$11-Assumptions!$D$11)/(Assumptions!$F$11-Assumptions!$D$11),Assumptions!$D$11+SQRT('Random Draws'!H7*(Assumptions!$F$11-Assumptions!$D$11)*(Assumptions!$E$11-Assumptions!$D$11)),Assumptions!$F$11-SQRT((1-'Random Draws'!H7)*(Assumptions!$F$11-Assumptions!$D$11)*(Assumptions!$F$11-Assumptions!$E$11))) -> 0.17613477 | K7: =MAX(G7,I7+Assumptions!$D$21) -> 0.074326112 | L7: =(F7-Assumptions!$D$15)*(1-H7)+Assumptions!$D$15-J7 -> 0.14547372 | M7: =Assumptions!$D$14*(1+E7)^1*L7-Assumptions!$D$14*(1+E7)^0*E7*Assumptions!$D$16 -> 22.790515 | N7: =Assumptions!$D$14*(1+E7)^2*L7-Assumptions!$D$14*(1+E7)^1*E7*Assumptions!$D$16 -> 25.100133 | O7: =Assumptions!$D$14*(1+E7)^3*L7-Assumptions!$D$14*(1+E7)^2*E7*Assumptions!$D$16 -> 27.64381 | P7: =Assumptions!$D$14*(1+E7)^4*L7-Assumptions!$D$14*(1+E7)^3*E7*Assumptions!$D$16 -> 30.445268 | Q7: =Assumptions!$D$14*(1+E7)^5*L7-Assumptions!$D$14*(1+E7)^4*E7*Assumptions!$D$16 -> 33.530628 | R7: =M7/(1+K7)+N7/(1+K7)^2+O7/(1+K7)^3+P7/(1+K7)^4+Q7/(1+K7)^5 -> 111.53915 | S7: =Q7*(1+I7)/(K7-I7) -> 707.9456 | T7: =R7+S7/(1+K7)^5 -> 606.21332 | U7: =(T7-Assumptions!$D$17)/Assumptions!$D$18 -> 16.848533
B8: 3 | C8: =NORMSDIST('Random Draws'!C8) -> 0.47635361 | D8: =NORMSDIST(Assumptions!$D$22*'Random Draws'!C8+SQRT(1-Assumptions!$D$22^2)*'Random Draws'!D8) -> 0.63431769 | E8: =IF(C8<(Assumptions!$E$6-Assumptions!$D$6)/(Assumptions!$F$6-Assumptions!$D$6),Assumptions!$D$6+SQRT(C8*(Assumptions!$F$6-Assumptions!$D$6)*(Assumptions!$E$6-Assumptions!$D$6)),Assumptions!$F$6-SQRT((1-C8)*(Assumptions!$F$6-Assumptions!$D$6)*(Assumptions!$F$6-Assumptions!$E$6))) -> 0.088803361 | F8: =IF(D8<(Assumptions!$E$7-Assumptions!$D$7)/(Assumptions!$F$7-Assumptions!$D$7),Assumptions!$D$7+SQRT(D8*(Assumptions!$F$7-Assumptions!$D$7)*(Assumptions!$E$7-Assumptions!$D$7)),Assumptions!$F$7-SQRT((1-D8)*(Assumptions!$F$7-Assumptions!$D$7)*(Assumptions!$F$7-Assumptions!$E$7))) -> 0.42175436 | G8: =MIN(Assumptions!$D$24,MAX(Assumptions!$D$23,Assumptions!$D$8+Assumptions!$E$8*'Random Draws'!E8)) -> 0.081999485 | H8: =IF('Random Draws'!F8<(Assumptions!$E$9-Assumptions!$D$9)/(Assumptions!$F$9-Assumptions!$D$9),Assumptions!$D$9+SQRT('Random Draws'!F8*(Assumptions!$F$9-Assumptions!$D$9)*(Assumptions!$E$9-Assumptions!$D$9)),Assumptions!$F$9-SQRT((1-'Random Draws'!F8)*(Assumptions!$F$9-Assumptions!$D$9)*(Assumptions!$F$9-Assumptions!$E$9))) -> 0.27727538 | I8: =IF('Random Draws'!G8<(Assumptions!$E$10-Assumptions!$D$10)/(Assumptions!$F$10-Assumptions!$D$10),Assumptions!$D$10+SQRT('Random Draws'!G8*(Assumptions!$F$10-Assumptions!$D$10)*(Assumptions!$E$10-Assumptions!$D$10)),Assumptions!$F$10-SQRT((1-'Random Draws'!G8)*(Assumptions!$F$10-Assumptions!$D$10)*(Assumptions!$F$10-Assumptions!$E$10))) -> 0.014071175 | J8: =IF('Random Draws'!H8<(Assumptions!$E$11-Assumptions!$D$11)/(Assumptions!$F$11-Assumptions!$D$11),Assumptions!$D$11+SQRT('Random Draws'!H8*(Assumptions!$F$11-Assumptions!$D$11)*(Assumptions!$E$11-Assumptions!$D$11)),Assumptions!$F$11-SQRT((1-'Random Draws'!H8)*(Assumptions!$F$11-Assumptions!$D$11)*(Assumptions!$F$11-Assumptions!$E$11))) -> 0.1945813 | K8: =MAX(G8,I8+Assumptions!$D$21) -> 0.081999485 | L8: =(F8-Assumptions!$D$15)*(1-H8)+Assumptions!$D$15-J8 -> 0.14627676 | M8: =Assumptions!$D$14*(1+E8)^1*L8-Assumptions!$D$14*(1+E8)^0*E8*Assumptions!$D$16 -> 22.707366 | N8: =Assumptions!$D$14*(1+E8)^2*L8-Assumptions!$D$14*(1+E8)^1*E8*Assumptions!$D$16 -> 24.723857 | O8: =Assumptions!$D$14*(1+E8)^3*L8-Assumptions!$D$14*(1+E8)^2*E8*Assumptions!$D$16 -> 26.919418 | P8: =Assumptions!$D$14*(1+E8)^4*L8-Assumptions!$D$14*(1+E8)^3*E8*Assumptions!$D$16 -> 29.309953 | Q8: =Assumptions!$D$14*(1+E8)^5*L8-Assumptions!$D$14*(1+E8)^4*E8*Assumptions!$D$16 -> 31.912775 | R8: =M8/(1+K8)+N8/(1+K8)^2+O8/(1+K8)^3+P8/(1+K8)^4+Q8/(1+K8)^5 -> 106.26043 | S8: =Q8*(1+I8)/(K8-I8) -> 476.41146 | T8: =R8+S8/(1+K8)^5 -> 427.51324 | U8: =(T8-Assumptions!$D$17)/Assumptions!$D$18 -> 9.7005296
B9: 4 | C9: =NORMSDIST('Random Draws'!C9) -> 0.012661079 | D9: =NORMSDIST(Assumptions!$D$22*'Random Draws'!C9+SQRT(1-Assumptions!$D$22^2)*'Random Draws'!D9) -> 0.37093783 | E9: =IF(C9<(Assumptions!$E$6-Assumptions!$D$6)/(Assumptions!$F$6-Assumptions!$D$6),Assumptions!$D$6+SQRT(C9*(Assumptions!$F$6-Assumptions!$D$6)*(Assumptions!$E$6-Assumptions!$D$6)),Assumptions!$F$6-SQRT((1-C9)*(Assumptions!$F$6-Assumptions!$D$6)*(Assumptions!$F$6-Assumptions!$E$6))) -> 0.047956469 | F9: =IF(D9<(Assumptions!$E$7-Assumptions!$D$7)/(Assumptions!$F$7-Assumptions!$D$7),Assumptions!$D$7+SQRT(D9*(Assumptions!$F$7-Assumptions!$D$7)*(Assumptions!$E$7-Assumptions!$D$7)),Assumptions!$F$7-SQRT((1-D9)*(Assumptions!$F$7-Assumptions!$D$7)*(Assumptions!$F$7-Assumptions!$E$7))) -> 0.40717655 | G9: =MIN(Assumptions!$D$24,MAX(Assumptions!$D$23,Assumptions!$D$8+Assumptions!$E$8*'Random Draws'!E9)) -> 0.082794203 | H9: =IF('Random Draws'!F9<(Assumptions!$E$9-Assumptions!$D$9)/(Assumptions!$F$9-Assumptions!$D$9),Assumptions!$D$9+SQRT('Random Draws'!F9*(Assumptions!$F$9-Assumptions!$D$9)*(Assumptions!$E$9-Assumptions!$D$9)),Assumptions!$F$9-SQRT((1-'Random Draws'!F9)*(Assumptions!$F$9-Assumptions!$D$9)*(Assumptions!$F$9-Assumptions!$E$9))) -> 0.29715209 | I9: =IF('Random Draws'!G9<(Assumptions!$E$10-Assumptions!$D$10)/(Assumptions!$F$10-Assumptions!$D$10),Assumptions!$D$10+SQRT('Random Draws'!G9*(Assumptions!$F$10-Assumptions!$D$10)*(Assumptions!$E$10-Assumptions!$D$10)),Assumptions!$F$10-SQRT((1-'Random Draws'!G9)*(Assumptions!$F$10-Assumptions!$D$10)*(Assumptions!$F$10-Assumptions!$E$10))) -> 0.015543243 | J9: =IF('Random Draws'!H9<(Assumptions!$E$11-Assumptions!$D$11)/(Assumptions!$F$11-Assumptions!$D$11),Assumptions!$D$11+SQRT('Random Draws'!H9*(Assumptions!$F$11-Assumptions!$D$11)*(Assumptions!$E$11-Assumptions!$D$11)),Assumptions!$F$11-SQRT((1-'Random Draws'!H9)*(Assumptions!$F$11-Assumptions!$D$11)*(Assumptions!$F$11-Assumptions!$E$11))) -> 0.13208555 | K9: =MAX(G9,I9+Assumptions!$D$21) -> 0.082794203 | L9: =(F9-Assumptions!$D$15)*(1-H9)+Assumptions!$D$15-J9 -> 0.19272741 | M9: =Assumptions!$D$14*(1+E9)^1*L9-Assumptions!$D$14*(1+E9)^0*E9*Assumptions!$D$16 -> 29.07703 | N9: =Assumptions!$D$14*(1+E9)^2*L9-Assumptions!$D$14*(1+E9)^1*E9*Assumptions!$D$16 -> 30.471461 | O9: =Assumptions!$D$14*(1+E9)^3*L9-Assumptions!$D$14*(1+E9)^2*E9*Assumptions!$D$16 -> 31.932765 | P9: =Assumptions!$D$14*(1+E9)^4*L9-Assumptions!$D$14*(1+E9)^3*E9*Assumptions!$D$16 -> 33.464148 | Q9: =Assumptions!$D$14*(1+E9)^5*L9-Assumptions!$D$14*(1+E9)^4*E9*Assumptions!$D$16 -> 35.06897 | R9: =M9/(1+K9)+N9/(1+K9)^2+O9/(1+K9)^3+P9/(1+K9)^4+Q9/(1+K9)^5 -> 125.90214 | S9: =Q9*(1+I9)/(K9-I9) -> 529.56947 | T9: =R9+S9/(1+K9)^5 -> 481.69181 | U9: =(T9-Assumptions!$D$17)/Assumptions!$D$18 -> 11.867673
B10: 5 | C10: =NORMSDIST('Random Draws'!C10) -> 0.83847628 | D10: =NORMSDIST(Assumptions!$D$22*'Random Draws'!C10+SQRT(1-Assumptions!$D$22^2)*'Random Draws'!D10) -> 0.21524924 | E10: =IF(C10<(Assumptions!$E$6-Assumptions!$D$6)/(Assumptions!$F$6-Assumptions!$D$6),Assumptions!$D$6+SQRT(C10*(Assumptions!$F$6-Assumptions!$D$6)*(Assumptions!$E$6-Assumptions!$D$6)),Assumptions!$F$6-SQRT((1-C10)*(Assumptions!$F$6-Assumptions!$D$6)*(Assumptions!$F$6-Assumptions!$E$6))) -> 0.11158137 | F10: =IF(D10<(Assumptions!$E$7-Assumptions!$D$7)/(Assumptions!$F$7-Assumptions!$D$7),Assumptions!$D$7+SQRT(D10*(Assumptions!$F$7-Assumptions!$D$7)*(Assumptions!$E$7-Assumptions!$D$7)),Assumptions!$F$7-SQRT((1-D10)*(Assumptions!$F$7-Assumptions!$D$7)*(Assumptions!$F$7-Assumptions!$E$7))) -> 0.39593738 | G10: =MIN(Assumptions!$D$24,MAX(Assumptions!$D$23,Assumptions!$D$8+Assumptions!$E$8*'Random Draws'!E10)) -> 0.10079877 | H10: =IF('Random Draws'!F10<(Assumptions!$E$9-Assumptions!$D$9)/(Assumptions!$F$9-Assumptions!$D$9),Assumptions!$D$9+SQRT('Random Draws'!F10*(Assumptions!$F$9-Assumptions!$D$9)*(Assumptions!$E$9-Assumptions!$D$9)),Assumptions!$F$9-SQRT((1-'Random Draws'!F10)*(Assumptions!$F$9-Assumptions!$D$9)*(Assumptions!$F$9-Assumptions!$E$9))) -> 0.2576402 | I10: =IF('Random Draws'!G10<(Assumptions!$E$10-Assumptions!$D$10)/(Assumptions!$F$10-Assumptions!$D$10),Assumptions!$D$10+SQRT('Random Draws'!G10*(Assumptions!$F$10-Assumptions!$D$10)*(Assumptions!$E$10-Assumptions!$D$10)),Assumptions!$F$10-SQRT((1-'Random Draws'!G10)*(Assumptions!$F$10-Assumptions!$D$10)*(Assumptions!$F$10-Assumptions!$E$10))) -> 0.016446405 | J10: =IF('Random Draws'!H10<(Assumptions!$E$11-Assumptions!$D$11)/(Assumptions!$F$11-Assumptions!$D$11),Assumptions!$D$11+SQRT('Random Draws'!H10*(Assumptions!$F$11-Assumptions!$D$11)*(Assumptions!$E$11-Assumptions!$D$11)),Assumptions!$F$11-SQRT((1-'Random Draws'!H10)*(Assumptions!$F$11-Assumptions!$D$11)*(Assumptions!$F$11-Assumptions!$E$11))) -> 0.16738793 | K10: =MAX(G10,I10+Assumptions!$D$21) -> 0.10079877 | L10: =(F10-Assumptions!$D$15)*(1-H10)+Assumptions!$D$15-J10 -> 0.16003329 | M10: =Assumptions!$D$14*(1+E10)^1*L10-Assumptions!$D$14*(1+E10)^0*E10*Assumptions!$D$16 -> 25.308675 | N10: =Assumptions!$D$14*(1+E10)^2*L10-Assumptions!$D$14*(1+E10)^1*E10*Assumptions!$D$16 -> 28.132651 | O10: =Assumptions!$D$14*(1+E10)^3*L10-Assumptions!$D$14*(1+E10)^2*E10*Assumptions!$D$16 -> 31.271731 | P10: =Assumptions!$D$14*(1+E10)^4*L10-Assumptions!$D$14*(1+E10)^3*E10*Assumptions!$D$16 -> 34.761074 | Q10: =Assumptions!$D$14*(1+E10)^5*L10-Assumptions!$D$14*(1+E10)^4*E10*Assumptions!$D$16 -> 38.639762 | R10: =M10/(1+K10)+N10/(1+K10)^2+O10/(1+K10)^3+P10/(1+K10)^4+Q10/(1+K10)^5 -> 117.23017 | S10: =Q10*(1+I10)/(K10-I10) -> 465.60934 | T10: =R10+S10/(1+K10)^5 -> 405.28954 | U10: =(T10-Assumptions!$D$17)/Assumptions!$D$18 -> 8.8115818
B11: 6 | C11: =NORMSDIST('Random Draws'!C11) -> 0.99292598 | D11: =NORMSDIST(Assumptions!$D$22*'Random Draws'!C11+SQRT(1-Assumptions!$D$22^2)*'Random Draws'!D11) -> 0.61715956 | E11: =IF(C11<(Assumptions!$E$6-Assumptions!$D$6)/(Assumptions!$F$6-Assumptions!$D$6),Assumptions!$D$6+SQRT(C11*(Assumptions!$F$6-Assumptions!$D$6)*(Assumptions!$E$6-Assumptions!$D$6)),Assumptions!$F$6-SQRT((1-C11)*(Assumptions!$F$6-Assumptions!$D$6)*(Assumptions!$F$6-Assumptions!$E$6))) -> 0.13405272 | F11: =IF(D11<(Assumptions!$E$7-Assumptions!$D$7)/(Assumptions!$F$7-Assumptions!$D$7),Assumptions!$D$7+SQRT(D11*(Assumptions!$F$7-Assumptions!$D$7)*(Assumptions!$E$7-Assumptions!$D$7)),Assumptions!$F$7-SQRT((1-D11)*(Assumptions!$F$7-Assumptions!$D$7)*(Assumptions!$F$7-Assumptions!$E$7))) -> 0.42086738 | G11: =MIN(Assumptions!$D$24,MAX(Assumptions!$D$23,Assumptions!$D$8+Assumptions!$E$8*'Random Draws'!E11)) -> 0.10142449 | H11: =IF('Random Draws'!F11<(Assumptions!$E$9-Assumptions!$D$9)/(Assumptions!$F$9-Assumptions!$D$9),Assumptions!$D$9+SQRT('Random Draws'!F11*(Assumptions!$F$9-Assumptions!$D$9)*(Assumptions!$E$9-Assumptions!$D$9)),Assumptions!$F$9-SQRT((1-'Random Draws'!F11)*(Assumptions!$F$9-Assumptions!$D$9)*(Assumptions!$F$9-Assumptions!$E$9))) -> 0.32333019 | I11: =IF('Random Draws'!G11<(Assumptions!$E$10-Assumptions!$D$10)/(Assumptions!$F$10-Assumptions!$D$10),Assumptions!$D$10+SQRT('Random Draws'!G11*(Assumptions!$F$10-Assumptions!$D$10)*(Assumptions!$E$10-Assumptions!$D$10)),Assumptions!$F$10-SQRT((1-'Random Draws'!G11)*(Assumptions!$F$10-Assumptions!$D$10)*(Assumptions!$F$10-Assumptions!$E$10))) -> 0.01907002 | J11: =IF('Random Draws'!H11<(Assumptions!$E$11-Assumptions!$D$11)/(Assumptions!$F$11-Assumptions!$D$11),Assumptions!$D$11+SQRT('Random Draws'!H11*(Assumptions!$F$11-Assumptions!$D$11)*(Assumptions!$E$11-Assumptions!$D$11)),Assumptions!$F$11-SQRT((1-'Random Draws'!H11)*(Assumptions!$F$11-Assumptions!$D$11)*(Assumptions!$F$11-Assumptions!$E$11))) -> 0.20979799 | K11: =MAX(G11,I11+Assumptions!$D$21) -> 0.10142449 | L11: =(F11-Assumptions!$D$15)*(1-H11)+Assumptions!$D$15-J11 -> 0.11702319 | M11: =Assumptions!$D$14*(1+E11)^1*L11-Assumptions!$D$14*(1+E11)^0*E11*Assumptions!$D$16 -> 18.659888 | N11: =Assumptions!$D$14*(1+E11)^2*L11-Assumptions!$D$14*(1+E11)^1*E11*Assumptions!$D$16 -> 21.161296 | O11: =Assumptions!$D$14*(1+E11)^3*L11-Assumptions!$D$14*(1+E11)^2*E11*Assumptions!$D$16 -> 23.998026 | P11: =Assumptions!$D$14*(1+E11)^4*L11-Assumptions!$D$14*(1+E11)^3*E11*Assumptions!$D$16 -> 27.215027 | Q11: =Assumptions!$D$14*(1+E11)^5*L11-Assumptions!$D$14*(1+E11)^4*E11*Assumptions!$D$16 -> 30.863275 | R11: =M11/(1+K11)+N11/(1+K11)^2+O11/(1+K11)^3+P11/(1+K11)^4+Q11/(1+K11)^5 -> 89.877585 | S11: =Q11*(1+I11)/(K11-I11) -> 381.90809 | T11: =R11+S11/(1+K11)^5 -> 325.48297 | U11: =(T11-Assumptions!$D$17)/Assumptions!$D$18 -> 5.619319
B12: 7 | C12: =NORMSDIST('Random Draws'!C12) -> 0.99347723 | D12: =NORMSDIST(Assumptions!$D$22*'Random Draws'!C12+SQRT(1-Assumptions!$D$22^2)*'Random Draws'!D12) -> 0.64852886 | E12: =IF(C12<(Assumptions!$E$6-Assumptions!$D$6)/(Assumptions!$F$6-Assumptions!$D$6),Assumptions!$D$6+SQRT(C12*(Assumptions!$F$6-Assumptions!$D$6)*(Assumptions!$E$6-Assumptions!$D$6)),Assumptions!$F$6-SQRT((1-C12)*(Assumptions!$F$6-Assumptions!$D$6)*(Assumptions!$F$6-Assumptions!$E$6))) -> 0.13428915 | F12: =IF(D12<(Assumptions!$E$7-Assumptions!$D$7)/(Assumptions!$F$7-Assumptions!$D$7),Assumptions!$D$7+SQRT(D12*(Assumptions!$F$7-Assumptions!$D$7)*(Assumptions!$E$7-Assumptions!$D$7)),Assumptions!$F$7-SQRT((1-D12)*(Assumptions!$F$7-Assumptions!$D$7)*(Assumptions!$F$7-Assumptions!$E$7))) -> 0.42250487 | G12: =MIN(Assumptions!$D$24,MAX(Assumptions!$D$23,Assumptions!$D$8+Assumptions!$E$8*'Random Draws'!E12)) -> 0.086375776 | H12: =IF('Random Draws'!F12<(Assumptions!$E$9-Assumptions!$D$9)/(Assumptions!$F$9-Assumptions!$D$9),Assumptions!$D$9+SQRT('Random Draws'!F12*(Assumptions!$F$9-Assumptions!$D$9)*(Assumptions!$E$9-Assumptions!$D$9)),Assumptions!$F$9-SQRT((1-'Random Draws'!F12)*(Assumptions!$F$9-Assumptions!$D$9)*(Assumptions!$F$9-Assumptions!$E$9))) -> 0.25526919 | I12: =IF('Random Draws'!G12<(Assumptions!$E$10-Assumptions!$D$10)/(Assumptions!$F$10-Assumptions!$D$10),Assumptions!$D$10+SQRT('Random Draws'!G12*(Assumptions!$F$10-Assumptions!$D$10)*(Assumptions!$E$10-Assumptions!$D$10)),Assumptions!$F$10-SQRT((1-'Random Draws'!G12)*(Assumptions!$F$10-Assumptions!$D$10)*(Assumptions!$F$10-Assumptions!$E$10))) -> 0.021294758 | J12: =IF('Random Draws'!H12<(Assumptions!$E$11-Assumptions!$D$11)/(Assumptions!$F$11-Assumptions!$D$11),Assumptions!$D$11+SQRT('Random Draws'!H12*(Assumptions!$F$11-Assumptions!$D$11)*(Assumptions!$E$11-Assumptions!$D$11)),Assumptions!$F$11-SQRT((1-'Random Draws'!H12)*(Assumptions!$F$11-Assumptions!$D$11)*(Assumptions!$F$11-Assumptions!$E$11))) -> 0.16162856 | K12: =MAX(G12,I12+Assumptions!$D$21) -> 0.086375776 | L12: =(F12-Assumptions!$D$15)*(1-H12)+Assumptions!$D$15-J12 -> 0.18620883 | M12: =Assumptions!$D$14*(1+E12)^1*L12-Assumptions!$D$14*(1+E12)^0*E12*Assumptions!$D$16 -> 30.041967 | N12: =Assumptions!$D$14*(1+E12)^2*L12-Assumptions!$D$14*(1+E12)^1*E12*Assumptions!$D$16 -> 34.076278 | O12: =Assumptions!$D$14*(1+E12)^3*L12-Assumptions!$D$14*(1+E12)^2*E12*Assumptions!$D$16 -> 38.652352 | P12: =Assumptions!$D$14*(1+E12)^4*L12-Assumptions!$D$14*(1+E12)^3*E12*Assumptions!$D$16 -> 43.842943 | Q12: =Assumptions!$D$14*(1+E12)^5*L12-Assumptions!$D$14*(1+E12)^4*E12*Assumptions!$D$16 -> 49.730575 | R12: =M12/(1+K12)+N12/(1+K12)^2+O12/(1+K12)^3+P12/(1+K12)^4+Q12/(1+K12)^5 -> 151.013 | S12: =Q12*(1+I12)/(K12-I12) -> 780.40536 | T12: =R12+S12/(1+K12)^5 -> 666.74001 | U12: =(T12-Assumptions!$D$17)/Assumptions!$D$18 -> 19.2696
B13: 8 | C13: =NORMSDIST('Random Draws'!C13) -> 0.69139487 | D13: =NORMSDIST(Assumptions!$D$22*'Random Draws'!C13+SQRT(1-Assumptions!$D$22^2)*'Random Draws'!D13) -> 0.52619385 | E13: =IF(C13<(Assumptions!$E$6-Assumptions!$D$6)/(Assumptions!$F$6-Assumptions!$D$6),Assumptions!$D$6+SQRT(C13*(Assumptions!$F$6-Assumptions!$D$6)*(Assumptions!$E$6-Assumptions!$D$6)),Assumptions!$F$6-SQRT((1-C13)*(Assumptions!$F$6-Assumptions!$D$6)*(Assumptions!$F$6-Assumptions!$E$6))) -> 0.10071863 | F13: =IF(D13<(Assumptions!$E$7-Assumptions!$D$7)/(Assumptions!$F$7-Assumptions!$D$7),Assumptions!$D$7+SQRT(D13*(Assumptions!$F$7-Assumptions!$D$7)*(Assumptions!$E$7-Assumptions!$D$7)),Assumptions!$F$7-SQRT((1-D13)*(Assumptions!$F$7-Assumptions!$D$7)*(Assumptions!$F$7-Assumptions!$E$7))) -> 0.41618864 | G13: =MIN(Assumptions!$D$24,MAX(Assumptions!$D$23,Assumptions!$D$8+Assumptions!$E$8*'Random Draws'!E13)) -> 0.07083763 | H13: =IF('Random Draws'!F13<(Assumptions!$E$9-Assumptions!$D$9)/(Assumptions!$F$9-Assumptions!$D$9),Assumptions!$D$9+SQRT('Random Draws'!F13*(Assumptions!$F$9-Assumptions!$D$9)*(Assumptions!$E$9-Assumptions!$D$9)),Assumptions!$F$9-SQRT((1-'Random Draws'!F13)*(Assumptions!$F$9-Assumptions!$D$9)*(Assumptions!$F$9-Assumptions!$E$9))) -> 0.29987548 | I13: =IF('Random Draws'!G13<(Assumptions!$E$10-Assumptions!$D$10)/(Assumptions!$F$10-Assumptions!$D$10),Assumptions!$D$10+SQRT('Random Draws'!G13*(Assumptions!$F$10-Assumptions!$D$10)*(Assumptions!$E$10-Assumptions!$D$10)),Assumptions!$F$10-SQRT((1-'Random Draws'!G13)*(Assumptions!$F$10-Assumptions!$D$10)*(Assumptions!$F$10-Assumptions!$E$10))) -> 0.014309291 | J13: =IF('Random Draws'!H13<(Assumptions!$E$11-Assumptions!$D$11)/(Assumptions!$F$11-Assumptions!$D$11),Assumptions!$D$11+SQRT('Random Draws'!H13*(Assumptions!$F$11-Assumptions!$D$11)*(Assumptions!$E$11-Assumptions!$D$11)),Assumptions!$F$11-SQRT((1-'Random Draws'!H13)*(Assumptions!$F$11-Assumptions!$D$11)*(Assumptions!$F$11-Assumptions!$E$11))) -> 0.15407121 | K13: =MAX(G13,I13+Assumptions!$D$21) -> 0.07083763 | L13: =(F13-Assumptions!$D$15)*(1-H13)+Assumptions!$D$15-J13 -> 0.17629647 | M13: =Assumptions!$D$14*(1+E13)^1*L13-Assumptions!$D$14*(1+E13)^0*E13*Assumptions!$D$16 -> 27.699532 | N13: =Assumptions!$D$14*(1+E13)^2*L13-Assumptions!$D$14*(1+E13)^1*E13*Assumptions!$D$16 -> 30.489391 | O13: =Assumptions!$D$14*(1+E13)^3*L13-Assumptions!$D$14*(1+E13)^2*E13*Assumptions!$D$16 -> 33.560241 | P13: =Assumptions!$D$14*(1+E13)^4*L13-Assumptions!$D$14*(1+E13)^3*E13*Assumptions!$D$16 -> 36.940382 | Q13: =Assumptions!$D$14*(1+E13)^5*L13-Assumptions!$D$14*(1+E13)^4*E13*Assumptions!$D$16 -> 40.660967 | R13: =M13/(1+K13)+N13/(1+K13)^2+O13/(1+K13)^3+P13/(1+K13)^4+Q13/(1+K13)^5 -> 136.75812 | S13: =Q13*(1+I13)/(K13-I13) -> 729.59506 | T13: =R13+S13/(1+K13)^5 -> 654.91797 | U13: =(T13-Assumptions!$D$17)/Assumptions!$D$18 -> 18.796719
B14: 9 | C14: =NORMSDIST('Random Draws'!C14) -> 0.26979653 | D14: =NORMSDIST(Assumptions!$D$22*'Random Draws'!C14+SQRT(1-Assumptions!$D$22^2)*'Random Draws'!D14) -> 0.29206047 | E14: =IF(C14<(Assumptions!$E$6-Assumptions!$D$6)/(Assumptions!$F$6-Assumptions!$D$6),Assumptions!$D$6+SQRT(C14*(Assumptions!$F$6-Assumptions!$D$6)*(Assumptions!$E$6-Assumptions!$D$6)),Assumptions!$F$6-SQRT((1-C14)*(Assumptions!$F$6-Assumptions!$D$6)*(Assumptions!$F$6-Assumptions!$E$6))) -> 0.076728499 | F14: =IF(D14<(Assumptions!$E$7-Assumptions!$D$7)/(Assumptions!$F$7-Assumptions!$D$7),Assumptions!$D$7+SQRT(D14*(Assumptions!$F$7-Assumptions!$D$7)*(Assumptions!$E$7-Assumptions!$D$7)),Assumptions!$F$7-SQRT((1-D14)*(Assumptions!$F$7-Assumptions!$D$7)*(Assumptions!$F$7-Assumptions!$E$7))) -> 0.40186123 | G14: =MIN(Assumptions!$D$24,MAX(Assumptions!$D$23,Assumptions!$D$8+Assumptions!$E$8*'Random Draws'!E14)) -> 0.085893586 | H14: =IF('Random Draws'!F14<(Assumptions!$E$9-Assumptions!$D$9)/(Assumptions!$F$9-Assumptions!$D$9),Assumptions!$D$9+SQRT('Random Draws'!F14*(Assumptions!$F$9-Assumptions!$D$9)*(Assumptions!$E$9-Assumptions!$D$9)),Assumptions!$F$9-SQRT((1-'Random Draws'!F14)*(Assumptions!$F$9-Assumptions!$D$9)*(Assumptions!$F$9-Assumptions!$E$9))) -> 0.28438765 | I14: =IF('Random Draws'!G14<(Assumptions!$E$10-Assumptions!$D$10)/(Assumptions!$F$10-Assumptions!$D$10),Assumptions!$D$10+SQRT('Random Draws'!G14*(Assumptions!$F$10-Assumptions!$D$10)*(Assumptions!$E$10-Assumptions!$D$10)),Assumptions!$F$10-SQRT((1-'Random Draws'!G14)*(Assumptions!$F$10-Assumptions!$D$10)*(Assumptions!$F$10-Assumptions!$E$10))) -> 0.016964209 | J14: =IF('Random Draws'!H14<(Assumptions!$E$11-Assumptions!$D$11)/(Assumptions!$F$11-Assumptions!$D$11),Assumptions!$D$11+SQRT('Random Draws'!H14*(Assumptions!$F$11-Assumptions!$D$11)*(Assumptions!$E$11-Assumptions!$D$11)),Assumptions!$F$11-SQRT((1-'Random Draws'!H14)*(Assumptions!$F$11-Assumptions!$D$11)*(Assumptions!$F$11-Assumptions!$E$11))) -> 0.16647024 | K14: =MAX(G14,I14+Assumptions!$D$21) -> 0.085893586 | L14: =(F14-Assumptions!$D$15)*(1-H14)+Assumptions!$D$15-J14 -> 0.15807702 | M14: =Assumptions!$D$14*(1+E14)^1*L14-Assumptions!$D$14*(1+E14)^0*E14*Assumptions!$D$16 -> 24.346105 | N14: =Assumptions!$D$14*(1+E14)^2*L14-Assumptions!$D$14*(1+E14)^1*E14*Assumptions!$D$16 -> 26.214146 | O14: =Assumptions!$D$14*(1+E14)^3*L14-Assumptions!$D$14*(1+E14)^2*E14*Assumptions!$D$16 -> 28.225518 | P14: =Assumptions!$D$14*(1+E14)^4*L14-Assumptions!$D$14*(1+E14)^3*E14*Assumptions!$D$16 -> 30.391219 | Q14: =Assumptions!$D$14*(1+E14)^5*L14-Assumptions!$D$14*(1+E14)^4*E14*Assumptions!$D$16 -> 32.723092 | R14: =M14/(1+K14)+N14/(1+K14)^2+O14/(1+K14)^3+P14/(1+K14)^4+Q14/(1+K14)^5 -> 110.22531 | S14: =Q14*(1+I14)/(K14-I14) -> 482.78709 | T14: =R14+S14/(1+K14)^5 -> 429.98175 | U14: =(T14-Assumptions!$D$17)/Assumptions!$D$18 -> 9.7992702
B15: 10 | C15: =NORMSDIST('Random Draws'!C15) -> 0.823045 | D15: =NORMSDIST(Assumptions!$D$22*'Random Draws'!C15+SQRT(1-Assumptions!$D$22^2)*'Random Draws'!D15) -> 0.74518449 | E15: =IF(C15<(Assumptions!$E$6-Assumptions!$D$6)/(Assumptions!$F$6-Assumptions!$D$6),Assumptions!$D$6+SQRT(C15*(Assumptions!$F$6-Assumptions!$D$6)*(Assumptions!$E$6-Assumptions!$D$6)),Assumptions!$F$6-SQRT((1-C15)*(Assumptions!$F$6-Assumptions!$D$6)*(Assumptions!$F$6-Assumptions!$E$6))) -> 0.11025483 | F15: =IF(D15<(Assumptions!$E$7-Assumptions!$D$7)/(Assumptions!$F$7-Assumptions!$D$7),Assumptions!$D$7+SQRT(D15*(Assumptions!$F$7-Assumptions!$D$7)*(Assumptions!$E$7-Assumptions!$D$7)),Assumptions!$F$7-SQRT((1-D15)*(Assumptions!$F$7-Assumptions!$D$7)*(Assumptions!$F$7-Assumptions!$E$7))) -> 0.42807412 | G15: =MIN(Assumptions!$D$24,MAX(Assumptions!$D$23,Assumptions!$D$8+Assumptions!$E$8*'Random Draws'!E15)) -> 0.072684625 | H15: =IF('Random Draws'!F15<(Assumptions!$E$9-Assumptions!$D$9)/(Assumptions!$F$9-Assumptions!$D$9),Assumptions!$D$9+SQRT('Random Draws'!F15*(Assumptions!$F$9-Assumptions!$D$9)*(Assumptions!$E$9-Assumptions!$D$9)),Assumptions!$F$9-SQRT((1-'Random Draws'!F15)*(Assumptions!$F$9-Assumptions!$D$9)*(Assumptions!$F$9-Assumptions!$E$9))) -> 0.27454476 | I15: =IF('Random Draws'!G15<(Assumptions!$E$10-Assumptions!$D$10)/(Assumptions!$F$10-Assumptions!$D$10),Assumptions!$D$10+SQRT('Random Draws'!G15*(Assumptions!$F$10-Assumptions!$D$10)*(Assumptions!$E$10-Assumptions!$D$10)),Assumptions!$F$10-SQRT((1-'Random Draws'!G15)*(Assumptions!$F$10-Assumptions!$D$10)*(Assumptions!$F$10-Assumptions!$E$10))) -> 0.023108314 | J15: =IF('Random Draws'!H15<(Assumptions!$E$11-Assumptions!$D$11)/(Assumptions!$F$11-Assumptions!$D$11),Assumptions!$D$11+SQRT('Random Draws'!H15*(Assumptions!$F$11-Assumptions!$D$11)*(Assumptions!$E$11-Assumptions!$D$11)),Assumptions!$F$11-SQRT((1-'Random Draws'!H15)*(Assumptions!$F$11-Assumptions!$D$11)*(Assumptions!$F$11-Assumptions!$E$11))) -> 0.18427983 | K15: =MAX(G15,I15+Assumptions!$D$21) -> 0.072684625 | L15: =(F15-Assumptions!$D$15)*(1-H15)+Assumptions!$D$15-J15 -> 0.16195959 | M15: =Assumptions!$D$14*(1+E15)^1*L15-Assumptions!$D$14*(1+E15)^0*E15*Assumptions!$D$16 -> 25.593773 | N15: =Assumptions!$D$14*(1+E15)^2*L15-Assumptions!$D$14*(1+E15)^1*E15*Assumptions!$D$16 -> 28.41561 | O15: =Assumptions!$D$14*(1+E15)^3*L15-Assumptions!$D$14*(1+E15)^2*E15*Assumptions!$D$16 -> 31.548568 | P15: =Assumptions!$D$14*(1+E15)^4*L15-Assumptions!$D$14*(1+E15)^3*E15*Assumptions!$D$16 -> 35.02695 | Q15: =Assumptions!$D$14*(1+E15)^5*L15-Assumptions!$D$14*(1+E15)^4*E15*Assumptions!$D$16 -> 38.888841 | R15: =M15/(1+K15)+N15/(1+K15)^2+O15/(1+K15)^3+P15/(1+K15)^4+Q15/(1+K15)^5 -> 127.95228 | S15: =Q15*(1+I15)/(K15-I15) -> 802.55056 | T15: =R15+S15/(1+K15)^5 -> 693.03512 | U15: =(T15-Assumptions!$D$17)/Assumptions!$D$18 -> 20.321405
B16: 11 | C16: =NORMSDIST('Random Draws'!C16) -> 0.021973619 | D16: =NORMSDIST(Assumptions!$D$22*'Random Draws'!C16+SQRT(1-Assumptions!$D$22^2)*'Random Draws'!D16) -> 0.11617985 | E16: =IF(C16<(Assumptions!$E$6-Assumptions!$D$6)/(Assumptions!$F$6-Assumptions!$D$6),Assumptions!$D$6+SQRT(C16*(Assumptions!$F$6-Assumptions!$D$6)*(Assumptions!$E$6-Assumptions!$D$6)),Assumptions!$F$6-SQRT((1-C16)*(Assumptions!$F$6-Assumptions!$D$6)*(Assumptions!$F$6-Assumptions!$E$6))) -> 0.050481798 | F16: =IF(D16<(Assumptions!$E$7-Assumptions!$D$7)/(Assumptions!$F$7-Assumptions!$D$7),Assumptions!$D$7+SQRT(D16*(Assumptions!$F$7-Assumptions!$D$7)*(Assumptions!$E$7-Assumptions!$D$7)),Assumptions!$F$7-SQRT((1-D16)*(Assumptions!$F$7-Assumptions!$D$7)*(Assumptions!$F$7-Assumptions!$E$7))) -> 0.38640226 | G16: =MIN(Assumptions!$D$24,MAX(Assumptions!$D$23,Assumptions!$D$8+Assumptions!$E$8*'Random Draws'!E16)) -> 0.078816548 | H16: =IF('Random Draws'!F16<(Assumptions!$E$9-Assumptions!$D$9)/(Assumptions!$F$9-Assumptions!$D$9),Assumptions!$D$9+SQRT('Random Draws'!F16*(Assumptions!$F$9-Assumptions!$D$9)*(Assumptions!$E$9-Assumptions!$D$9)),Assumptions!$F$9-SQRT((1-'Random Draws'!F16)*(Assumptions!$F$9-Assumptions!$D$9)*(Assumptions!$F$9-Assumptions!$E$9))) -> 0.27774353 | I16: =IF('Random Draws'!G16<(Assumptions!$E$10-Assumptions!$D$10)/(Assumptions!$F$10-Assumptions!$D$10),Assumptions!$D$10+SQRT('Random Draws'!G16*(Assumptions!$F$10-Assumptions!$D$10)*(Assumptions!$E$10-Assumptions!$D$10)),Assumptions!$F$10-SQRT((1-'Random Draws'!G16)*(Assumptions!$F$10-Assumptions!$D$10)*(Assumptions!$F$10-Assumptions!$E$10))) -> 0.014062312 | J16: =IF('Random Draws'!H16<(Assumptions!$E$11-Assumptions!$D$11)/(Assumptions!$F$11-Assumptions!$D$11),Assumptions!$D$11+SQRT('Random Draws'!H16*(Assumptions!$F$11-Assumptions!$D$11)*(Assumptions!$E$11-Assumptions!$D$11)),Assumptions!$F$11-SQRT((1-'Random Draws'!H16)*(Assumptions!$F$11-Assumptions!$D$11)*(Assumptions!$F$11-Assumptions!$E$11))) -> 0.1415003 | K16: =MAX(G16,I16+Assumptions!$D$21) -> 0.078816548 | L16: =(F16-Assumptions!$D$15)*(1-H16)+Assumptions!$D$15-J16 -> 0.17368789 | M16: =Assumptions!$D$14*(1+E16)^1*L16-Assumptions!$D$14*(1+E16)^0*E16*Assumptions!$D$16 -> 26.236519 | N16: =Assumptions!$D$14*(1+E16)^2*L16-Assumptions!$D$14*(1+E16)^1*E16*Assumptions!$D$16 -> 27.560986 | O16: =Assumptions!$D$14*(1+E16)^3*L16-Assumptions!$D$14*(1+E16)^2*E16*Assumptions!$D$16 -> 28.952314 | P16: =Assumptions!$D$14*(1+E16)^4*L16-Assumptions!$D$14*(1+E16)^3*E16*Assumptions!$D$16 -> 30.413879 | Q16: =Assumptions!$D$14*(1+E16)^5*L16-Assumptions!$D$14*(1+E16)^4*E16*Assumptions!$D$16 -> 31.949226 | R16: =M16/(1+K16)+N16/(1+K16)^2+O16/(1+K16)^3+P16/(1+K16)^4+Q16/(1+K16)^5 -> 115.37669 | S16: =Q16*(1+I16)/(K16-I16) -> 500.3303 | T16: =R16+S16/(1+K16)^5 -> 457.76491 | U16: =(T16-Assumptions!$D$17)/Assumptions!$D$18 -> 10.910596
B17: 12 | C17: =NORMSDIST('Random Draws'!C17) -> 0.31447627 | D17: =NORMSDIST(Assumptions!$D$22*'Random Draws'!C17+SQRT(1-Assumptions!$D$22^2)*'Random Draws'!D17) -> 0.95974599 | E17: =IF(C17<(Assumptions!$E$6-Assumptions!$D$6)/(Assumptions!$F$6-Assumptions!$D$6),Assumptions!$D$6+SQRT(C17*(Assumptions!$F$6-Assumptions!$D$6)*(Assumptions!$E$6-Assumptions!$D$6)),Assumptions!$F$6-SQRT((1-C17)*(Assumptions!$F$6-Assumptions!$D$6)*(Assumptions!$F$6-Assumptions!$E$6))) -> 0.079653264 | F17: =IF(D17<(Assumptions!$E$7-Assumptions!$D$7)/(Assumptions!$F$7-Assumptions!$D$7),Assumptions!$D$7+SQRT(D17*(Assumptions!$F$7-Assumptions!$D$7)*(Assumptions!$E$7-Assumptions!$D$7)),Assumptions!$F$7-SQRT((1-D17)*(Assumptions!$F$7-Assumptions!$D$7)*(Assumptions!$F$7-Assumptions!$E$7))) -> 0.44731079 | G17: =MIN(Assumptions!$D$24,MAX(Assumptions!$D$23,Assumptions!$D$8+Assumptions!$E$8*'Random Draws'!E17)) -> 0.076183311 | H17: =IF('Random Draws'!F17<(Assumptions!$E$9-Assumptions!$D$9)/(Assumptions!$F$9-Assumptions!$D$9),Assumptions!$D$9+SQRT('Random Draws'!F17*(Assumptions!$F$9-Assumptions!$D$9)*(Assumptions!$E$9-Assumptions!$D$9)),Assumptions!$F$9-SQRT((1-'Random Draws'!F17)*(Assumptions!$F$9-Assumptions!$D$9)*(Assumptions!$F$9-Assumptions!$E$9))) -> 0.25911655 | I17: =IF('Random Draws'!G17<(Assumptions!$E$10-Assumptions!$D$10)/(Assumptions!$F$10-Assumptions!$D$10),Assumptions!$D$10+SQRT('Random Draws'!G17*(Assumptions!$F$10-Assumptions!$D$10)*(Assumptions!$E$10-Assumptions!$D$10)),Assumptions!$F$10-SQRT((1-'Random Draws'!G17)*(Assumptions!$F$10-Assumptions!$D$10)*(Assumptions!$F$10-Assumptions!$E$10))) -> 0.014878821 | J17: =IF('Random Draws'!H17<(Assumptions!$E$11-Assumptions!$D$11)/(Assumptions!$F$11-Assumptions!$D$11),Assumptions!$D$11+SQRT('Random Draws'!H17*(Assumptions!$F$11-Assumptions!$D$11)*(Assumptions!$E$11-Assumptions!$D$11)),Assumptions!$F$11-SQRT((1-'Random Draws'!H17)*(Assumptions!$F$11-Assumptions!$D$11)*(Assumptions!$F$11-Assumptions!$E$11))) -> 0.15186201 | K17: =MAX(G17,I17+Assumptions!$D$21) -> 0.076183311 | L17: =(F17-Assumptions!$D$15)*(1-H17)+Assumptions!$D$15-J17 -> 0.2132283 | M17: =Assumptions!$D$14*(1+E17)^1*L17-Assumptions!$D$14*(1+E17)^0*E17*Assumptions!$D$16 -> 33.03434 | N17: =Assumptions!$D$14*(1+E17)^2*L17-Assumptions!$D$14*(1+E17)^1*E17*Assumptions!$D$16 -> 35.665633 | O17: =Assumptions!$D$14*(1+E17)^3*L17-Assumptions!$D$14*(1+E17)^2*E17*Assumptions!$D$16 -> 38.506517 | P17: =Assumptions!$D$14*(1+E17)^4*L17-Assumptions!$D$14*(1+E17)^3*E17*Assumptions!$D$16 -> 41.573687 | Q17: =Assumptions!$D$14*(1+E17)^5*L17-Assumptions!$D$14*(1+E17)^4*E17*Assumptions!$D$16 -> 44.885167 | R17: =M17/(1+K17)+N17/(1+K17)^2+O17/(1+K17)^3+P17/(1+K17)^4+Q17/(1+K17)^5 -> 154.47208 | S17: =Q17*(1+I17)/(K17-I17) -> 743.06149 | T17: =R17+S17/(1+K17)^5 -> 669.21868 | U17: =(T17-Assumptions!$D$17)/Assumptions!$D$18 -> 19.368747
... B2005: 2000 | C2005: =NORMSDIST('Random Draws'!C2005) -> 0.1721119 | D2005: =NORMSDIST(Assumptions!$D$22*'Random Draws'!C2005+SQRT(1-Assumptions!$D$22^2)*'Random Draws'!D2005) -> 0.95227585 | E2005: =IF(C2005<(Assumptions!$E$6-Assumptions!$D$6)/(Assumptions!$F$6-Assumptions!$D$6),Assumptions!$D$6+SQRT(C2005*(Assumptions!$F$6-Assumptions!$D$6)*(Assumptions!$E$6-Assumptions!$D$6)),Assumptions!$F$6-SQRT((1-C2005)*(Assumptions!$F$6-Assumptions!$D$6)*(Assumptions!$F$6-Assumptions!$E$6))) -> 0.069335294 | F2005: =IF(D2005<(Assumptions!$E$7-Assumptions!$D$7)/(Assumptions!$F$7-Assumptions!$D$7),Assumptions!$D$7+SQRT(D2005*(Assumptions!$F$7-Assumptions!$D$7)*(Assumptions!$E$7-Assumptions!$D$7)),Assumptions!$F$7-SQRT((1-D2005)*(Assumptions!$F$7-Assumptions!$D$7)*(Assumptions!$F$7-Assumptions!$E$7))) -> 0.44618347 | G2005: =MIN(Assumptions!$D$24,MAX(Assumptions!$D$23,Assumptions!$D$8+Assumptions!$E$8*'Random Draws'!E2005)) -> 0.069567616 | H2005: =IF('Random Draws'!F2005<(Assumptions!$E$9-Assumptions!$D$9)/(Assumptions!$F$9-Assumptions!$D$9),Assumptions!$D$9+SQRT('Random Draws'!F2005*(Assumptions!$F$9-Assumptions!$D$9)*(Assumptions!$E$9-Assumptions!$D$9)),Assumptions!$F$9-SQRT((1-'Random Draws'!F2005)*(Assumptions!$F$9-Assumptions!$D$9)*(Assumptions!$F$9-Assumptions!$E$9))) -> 0.24967444 | I2005: =IF('Random Draws'!G2005<(Assumptions!$E$10-Assumptions!$D$10)/(Assumptions!$F$10-Assumptions!$D$10),Assumptions!$D$10+SQRT('Random Draws'!G2005*(Assumptions!$F$10-Assumptions!$D$10)*(Assumptions!$E$10-Assumptions!$D$10)),Assumptions!$F$10-SQRT((1-'Random Draws'!G2005)*(Assumptions!$F$10-Assumptions!$D$10)*(Assumptions!$F$10-Assumptions!$E$10))) -> 0.020186164 | J2005: =IF('Random Draws'!H2005<(Assumptions!$E$11-Assumptions!$D$11)/(Assumptions!$F$11-Assumptions!$D$11),Assumptions!$D$11+SQRT('Random Draws'!H2005*(Assumptions!$F$11-Assumptions!$D$11)*(Assumptions!$E$11-Assumptions!$D$11)),Assumptions!$F$11-SQRT((1-'Random Draws'!H2005)*(Assumptions!$F$11-Assumptions!$D$11)*(Assumptions!$F$11-Assumptions!$E$11))) -> 0.14333379 | K2005: =MAX(G2005,I2005+Assumptions!$D$21) -> 0.069567616 | L2005: =(F2005-Assumptions!$D$15)*(1-H2005)+Assumptions!$D$15-J2005 -> 0.22390675 | M2005: =Assumptions!$D$14*(1+E2005)^1*L2005-Assumptions!$D$14*(1+E2005)^0*E2005*Assumptions!$D$16 -> 34.415943 | N2005: =Assumptions!$D$14*(1+E2005)^2*L2005-Assumptions!$D$14*(1+E2005)^1*E2005*Assumptions!$D$16 -> 36.802182 | O2005: =Assumptions!$D$14*(1+E2005)^3*L2005-Assumptions!$D$14*(1+E2005)^2*E2005*Assumptions!$D$16 -> 39.353872 | P2005: =Assumptions!$D$14*(1+E2005)^4*L2005-Assumptions!$D$14*(1+E2005)^3*E2005*Assumptions!$D$16 -> 42.082485 | Q2005: =Assumptions!$D$14*(1+E2005)^5*L2005-Assumptions!$D$14*(1+E2005)^4*E2005*Assumptions!$D$16 -> 45.000286 | R2005: =M2005/(1+K2005)+N2005/(1+K2005)^2+O2005/(1+K2005)^3+P2005/(1+K2005)^4+Q2005/(1+K2005)^5 -> 160.8173 | S2005: =Q2005*(1+I2005)/(K2005-I2005) -> 929.67436 | T2005: =R2005+S2005/(1+K2005)^5 -> 825.00316 | U2005: =(T2005-Assumptions!$D$17)/Assumptions!$D$18 -> 25.600126

Sheet Results
B2: Results
B3: Statistics of the 2,000 live iterations, value per share in €
B5: Statistic | C5: Live | E5: From € | F5: To € | G5: Iterations
B6: Mean | C6: =AVERAGE(Simulation!$U$6:$U$2005) -> 13.40285 | E6: 0 | F6: 2 | G6: =COUNTIFS(Simulation!$U$6:$U$2005,">"&E6,Simulation!$U$6:$U$2005,"<="&F6) -> 7
B7: Median (P50) | C7: =MEDIAN(Simulation!$U$6:$U$2005) -> 12.553903 | E7: 2 | F7: 4 | G7: =COUNTIFS(Simulation!$U$6:$U$2005,">"&E7,Simulation!$U$6:$U$2005,"<="&F7) -> 34
B8: Standard deviation | C8: =STDEV(Simulation!$U$6:$U$2005) -> 5.9594537 | E8: 4 | F8: 6 | G8: =COUNTIFS(Simulation!$U$6:$U$2005,">"&E8,Simulation!$U$6:$U$2005,"<="&F8) -> 101
B9: P5 | C9: =PERCENTILE(Simulation!$U$6:$U$2005,0.05) -> 5.4605247 | E9: 6 | F9: 8 | G9: =COUNTIFS(Simulation!$U$6:$U$2005,">"&E9,Simulation!$U$6:$U$2005,"<="&F9) -> 185
B10: P10 | C10: =PERCENTILE(Simulation!$U$6:$U$2005,0.1) -> 6.8168369 | E10: 8 | F10: 10 | G10: =COUNTIFS(Simulation!$U$6:$U$2005,">"&E10,Simulation!$U$6:$U$2005,"<="&F10) -> 287
B11: P25 | C11: =PERCENTILE(Simulation!$U$6:$U$2005,0.25) -> 9.3002311 | E11: 10 | F11: 12 | G11: =COUNTIFS(Simulation!$U$6:$U$2005,">"&E11,Simulation!$U$6:$U$2005,"<="&F11) -> 308
B12: P75 | C12: =PERCENTILE(Simulation!$U$6:$U$2005,0.75) -> 16.765063 | E12: 12 | F12: 14 | G12: =COUNTIFS(Simulation!$U$6:$U$2005,">"&E12,Simulation!$U$6:$U$2005,"<="&F12) -> 287
B13: P95 | C13: =PERCENTILE(Simulation!$U$6:$U$2005,0.95) -> 24.176302 | E13: 14 | F13: 16 | G13: =COUNTIFS(Simulation!$U$6:$U$2005,">"&E13,Simulation!$U$6:$U$2005,"<="&F13) -> 229
B14: Iterations | C14: =COUNT(Simulation!$U$6:$U$2005) -> 2000 | E14: 16 | F14: 18 | G14: =COUNTIFS(Simulation!$U$6:$U$2005,">"&E14,Simulation!$U$6:$U$2005,"<="&F14) -> 177
B15: P(value > market price) | C15: =COUNTIF(Simulation!$U$6:$U$2005,">"&Assumptions!$D$19)/C14 -> 0.58 | E15: 18 | F15: 20 | G15: =COUNTIFS(Simulation!$U$6:$U$2005,">"&E15,Simulation!$U$6:$U$2005,"<="&F15) -> 140
B16: P(value > base case) | C16: =COUNTIF(Simulation!$U$6:$U$2005,">"&'DCF Base Case'!C36)/C14 -> 0.329 | E16: 20 | F16: 22 | G16: =COUNTIFS(Simulation!$U$6:$U$2005,">"&E16,Simulation!$U$6:$U$2005,"<="&F16) -> 85
B17: P(value < €8.00) | C17: =COUNTIF(Simulation!$U$6:$U$2005,"<8")/C14 -> 0.1635 | E17: 22 | F17: 24 | G17: =COUNTIFS(Simulation!$U$6:$U$2005,">"&E17,Simulation!$U$6:$U$2005,"<="&F17) -> 57
E18: 24 | F18: 26 | G18: =COUNTIFS(Simulation!$U$6:$U$2005,">"&E18,Simulation!$U$6:$U$2005,"<="&F18) -> 30
E19: 26 | F19: 28 | G19: =COUNTIFS(Simulation!$U$6:$U$2005,">"&E19,Simulation!$U$6:$U$2005,"<="&F19) -> 24
E20: 28 | F20: 30 | G20: =COUNTIFS(Simulation!$U$6:$U$2005,">"&E20,Simulation!$U$6:$U$2005,"<="&F20) -> 12
E21: 30 | F21: 32 | G21: =COUNTIFS(Simulation!$U$6:$U$2005,">"&E21,Simulation!$U$6:$U$2005,"<="&F21) -> 14
E22: 32 | F22: 34 | G22: =COUNTIFS(Simulation!$U$6:$U$2005,">"&E22,Simulation!$U$6:$U$2005,"<="&F22) -> 12
E23: 34 | F23: 36 | G23: =COUNTIFS(Simulation!$U$6:$U$2005,">"&E23,Simulation!$U$6:$U$2005,"<="&F23) -> 3
E24: Outside €0 to €36 | G24: =C14-SUM(G6:G23) -> 8

Sheet Sensitivity
B2: Sensitivity
B3: Which uncertainty moves value most
B5: Driver | C5: Live correlation | D5: Rank correlation (50,000) | E5: Share of variance (50,000) | F5: Reading
B6: WACC | C6: =CORREL(Simulation!$G$6:$G$2005,Simulation!$U$6:$U$2005) -> -0.67931445 | D6: -0.63077714 | E6: 0.38372835 | F6: The largest single driver: it discounts every cash flow and the terminal value
B7: CapEx (% of revenue) | C7: =CORREL(Simulation!$J$6:$J$2005,Simulation!$U$6:$U$2005) -> -0.45329599 | D7: -0.47382949 | E7: 0.21652905 | F7: Every point of revenue spent on CapEx is lost free cash flow
B8: EBITDA margin | C8: =CORREL(Simulation!$F$6:$F$2005,Simulation!$U$6:$U$2005) -> 0.44170404 | D8: 0.4378483 | E8: 0.18489252 | F8: Moves with growth through the copula
B9: Revenue growth | C9: =CORREL(Simulation!$E$6:$E$2005,Simulation!$U$6:$U$2005) -> 0.40015529 | D9: 0.41723055 | E9: 0.16788976 | F9: Compounds over five years and into the terminal value
B10: Terminal growth | C10: =CORREL(Simulation!$I$6:$I$2005,Simulation!$U$6:$U$2005) -> 0.16024055 | D10: 0.15855076 | E10: 0.024244243 | F10: Small range, but it sits inside the terminal value
B11: Tax rate | C11: =CORREL(Simulation!$H$6:$H$2005,Simulation!$U$6:$U$2005) -> -0.14872139 | D11: -0.15347259 | E11: 0.022716094 | F11: Narrow most of the time; its tail is the windfall risk
B13: Live: Pearson correlation on this workbook's iterations. Rank (Spearman) correlations and shares of variance come from the Python 50,000-iteration run; the share is each squared rank correlation over the total.

Sheet Windfall
B2: Windfall tax as an event
B3: Same random numbers as the Simulation sheet; only the tax changes: an ordinary rate, plus a surcharge that either happens or not
B5: Iter | C5: Ordinary tax | D5: Surcharge? | E5: Tax | F5: FCF per € rev. | G5: Value per share | H5: Value if surcharge | I5: No surcharge | K5: Summary, value per share | L5: Event model | M5: If surcharge | N5: No surcharge
B6: 1 | C6: =IF('Random Draws'!F6<(Assumptions!$D$28-Assumptions!$D$27)/(Assumptions!$D$29-Assumptions!$D$27),Assumptions!$D$27+SQRT('Random Draws'!F6*(Assumptions!$D$29-Assumptions!$D$27)*(Assumptions!$D$28-Assumptions!$D$27)),Assumptions!$D$29-SQRT((1-'Random Draws'!F6)*(Assumptions!$D$29-Assumptions!$D$27)*(Assumptions!$D$29-Assumptions!$D$28))) -> 0.2743664 | D6: =IF('Random Draws'!I6<Assumptions!$D$30,1,0) -> 0 | E6: =C6+Assumptions!$D$31*D6 -> 0.2743664 | F6: =(Simulation!F6-Assumptions!$D$15)*(1-E6)+Assumptions!$D$15-Simulation!J6 -> 0.16308056 | G6: =((Assumptions!$D$14*(1+Simulation!E6)^1*F6-Assumptions!$D$14*(1+Simulation!E6)^0*Simulation!E6*Assumptions!$D$16)/(1+Simulation!K6)^1+(Assumptions!$D$14*(1+Simulation!E6)^2*F6-Assumptions!$D$14*(1+Simulation!E6)^1*Simulation!E6*Assumptions!$D$16)/(1+Simulation!K6)^2+(Assumptions!$D$14*(1+Simulation!E6)^3*F6-Assumptions!$D$14*(1+Simulation!E6)^2*Simulation!E6*Assumptions!$D$16)/(1+Simulation!K6)^3+(Assumptions!$D$14*(1+Simulation!E6)^4*F6-Assumptions!$D$14*(1+Simulation!E6)^3*Simulation!E6*Assumptions!$D$16)/(1+Simulation!K6)^4+(Assumptions!$D$14*(1+Simulation!E6)^5*F6-Assumptions!$D$14*(1+Simulation!E6)^4*Simulation!E6*Assumptions!$D$16)/(1+Simulation!K6)^5+(Assumptions!$D$14*(1+Simulation!E6)^5*F6-Assumptions!$D$14*(1+Simulation!E6)^4*Simulation!E6*Assumptions!$D$16)*(1+Simulation!I6)/(Simulation!K6-Simulation!I6)/(1+Simulation!K6)^5-Assumptions!$D$17)/Assumptions!$D$18 -> 16.82762 | H6: =IF(D6=1,G6,"") | I6: =IF(D6=0,G6,"") -> 16.82762 | K6: Iterations | L6: =COUNT($G$6:$G$2005) -> 2000 | M6: =COUNT($H$6:$H$2005) -> 509 | N6: =COUNT($I$6:$I$2005) -> 1491
B7: 2 | C7: =IF('Random Draws'!F7<(Assumptions!$D$28-Assumptions!$D$27)/(Assumptions!$D$29-Assumptions!$D$27),Assumptions!$D$27+SQRT('Random Draws'!F7*(Assumptions!$D$29-Assumptions!$D$27)*(Assumptions!$D$28-Assumptions!$D$27)),Assumptions!$D$29-SQRT((1-'Random Draws'!F7)*(Assumptions!$D$29-Assumptions!$D$27)*(Assumptions!$D$29-Assumptions!$D$28))) -> 0.27021836 | D7: =IF('Random Draws'!I7<Assumptions!$D$30,1,0) -> 0 | E7: =C7+Assumptions!$D$31*D7 -> 0.27021836 | F7: =(Simulation!F7-Assumptions!$D$15)*(1-E7)+Assumptions!$D$15-Simulation!J7 -> 0.15817604 | G7: =((Assumptions!$D$14*(1+Simulation!E7)^1*F7-Assumptions!$D$14*(1+Simulation!E7)^0*Simulation!E7*Assumptions!$D$16)/(1+Simulation!K7)^1+(Assumptions!$D$14*(1+Simulation!E7)^2*F7-Assumptions!$D$14*(1+Simulation!E7)^1*Simulation!E7*Assumptions!$D$16)/(1+Simulation!K7)^2+(Assumptions!$D$14*(1+Simulation!E7)^3*F7-Assumptions!$D$14*(1+Simulation!E7)^2*Simulation!E7*Assumptions!$D$16)/(1+Simulation!K7)^3+(Assumptions!$D$14*(1+Simulation!E7)^4*F7-Assumptions!$D$14*(1+Simulation!E7)^3*Simulation!E7*Assumptions!$D$16)/(1+Simulation!K7)^4+(Assumptions!$D$14*(1+Simulation!E7)^5*F7-Assumptions!$D$14*(1+Simulation!E7)^4*Simulation!E7*Assumptions!$D$16)/(1+Simulation!K7)^5+(Assumptions!$D$14*(1+Simulation!E7)^5*F7-Assumptions!$D$14*(1+Simulation!E7)^4*Simulation!E7*Assumptions!$D$16)*(1+Simulation!I7)/(Simulation!K7-Simulation!I7)/(1+Simulation!K7)^5-Assumptions!$D$17)/Assumptions!$D$18 -> 19.006797 | H7: =IF(D7=1,G7,"") | I7: =IF(D7=0,G7,"") -> 19.006797 | K7: Median | L7: =MEDIAN($G$6:$G$2005) -> 12.513107 | M7: =MEDIAN($H$6:$H$2005) -> 10.019161 | N7: =MEDIAN($I$6:$I$2005) -> 13.561292
B8: 3 | C8: =IF('Random Draws'!F8<(Assumptions!$D$28-Assumptions!$D$27)/(Assumptions!$D$29-Assumptions!$D$27),Assumptions!$D$27+SQRT('Random Draws'!F8*(Assumptions!$D$29-Assumptions!$D$27)*(Assumptions!$D$28-Assumptions!$D$27)),Assumptions!$D$29-SQRT((1-'Random Draws'!F8)*(Assumptions!$D$29-Assumptions!$D$27)*(Assumptions!$D$29-Assumptions!$D$28))) -> 0.25930328 | D8: =IF('Random Draws'!I8<Assumptions!$D$30,1,0) -> 0 | E8: =C8+Assumptions!$D$31*D8 -> 0.25930328 | F8: =(Simulation!F8-Assumptions!$D$15)*(1-E8)+Assumptions!$D$15-Simulation!J8 -> 0.1515202 | G8: =((Assumptions!$D$14*(1+Simulation!E8)^1*F8-Assumptions!$D$14*(1+Simulation!E8)^0*Simulation!E8*Assumptions!$D$16)/(1+Simulation!K8)^1+(Assumptions!$D$14*(1+Simulation!E8)^2*F8-Assumptions!$D$14*(1+Simulation!E8)^1*Simulation!E8*Assumptions!$D$16)/(1+Simulation!K8)^2+(Assumptions!$D$14*(1+Simulation!E8)^3*F8-Assumptions!$D$14*(1+Simulation!E8)^2*Simulation!E8*Assumptions!$D$16)/(1+Simulation!K8)^3+(Assumptions!$D$14*(1+Simulation!E8)^4*F8-Assumptions!$D$14*(1+Simulation!E8)^3*Simulation!E8*Assumptions!$D$16)/(1+Simulation!K8)^4+(Assumptions!$D$14*(1+Simulation!E8)^5*F8-Assumptions!$D$14*(1+Simulation!E8)^4*Simulation!E8*Assumptions!$D$16)/(1+Simulation!K8)^5+(Assumptions!$D$14*(1+Simulation!E8)^5*F8-Assumptions!$D$14*(1+Simulation!E8)^4*Simulation!E8*Assumptions!$D$16)*(1+Simulation!I8)/(Simulation!K8-Simulation!I8)/(1+Simulation!K8)^5-Assumptions!$D$17)/Assumptions!$D$18 -> 10.323944 | H8: =IF(D8=1,G8,"") | I8: =IF(D8=0,G8,"") -> 10.323944 | K8: P5 | L8: =PERCENTILE($G$6:$G$2005,0.05) -> 5.2127091 | M8: =PERCENTILE($H$6:$H$2005,0.05) -> 3.4823152 | N8: =PERCENTILE($I$6:$I$2005,0.05) -> 6.1831509
B9: 4 | C9: =IF('Random Draws'!F9<(Assumptions!$D$28-Assumptions!$D$27)/(Assumptions!$D$29-Assumptions!$D$27),Assumptions!$D$27+SQRT('Random Draws'!F9*(Assumptions!$D$29-Assumptions!$D$27)*(Assumptions!$D$28-Assumptions!$D$27)),Assumptions!$D$29-SQRT((1-'Random Draws'!F9)*(Assumptions!$D$29-Assumptions!$D$27)*(Assumptions!$D$29-Assumptions!$D$28))) -> 0.26497705 | D9: =IF('Random Draws'!I9<Assumptions!$D$30,1,0) -> 0 | E9: =C9+Assumptions!$D$31*D9 -> 0.26497705 | F9: =(Simulation!F9-Assumptions!$D$15)*(1-E9)+Assumptions!$D$15-Simulation!J9 -> 0.20164557 | G9: =((Assumptions!$D$14*(1+Simulation!E9)^1*F9-Assumptions!$D$14*(1+Simulation!E9)^0*Simulation!E9*Assumptions!$D$16)/(1+Simulation!K9)^1+(Assumptions!$D$14*(1+Simulation!E9)^2*F9-Assumptions!$D$14*(1+Simulation!E9)^1*Simulation!E9*Assumptions!$D$16)/(1+Simulation!K9)^2+(Assumptions!$D$14*(1+Simulation!E9)^3*F9-Assumptions!$D$14*(1+Simulation!E9)^2*Simulation!E9*Assumptions!$D$16)/(1+Simulation!K9)^3+(Assumptions!$D$14*(1+Simulation!E9)^4*F9-Assumptions!$D$14*(1+Simulation!E9)^3*Simulation!E9*Assumptions!$D$16)/(1+Simulation!K9)^4+(Assumptions!$D$14*(1+Simulation!E9)^5*F9-Assumptions!$D$14*(1+Simulation!E9)^4*Simulation!E9*Assumptions!$D$16)/(1+Simulation!K9)^5+(Assumptions!$D$14*(1+Simulation!E9)^5*F9-Assumptions!$D$14*(1+Simulation!E9)^4*Simulation!E9*Assumptions!$D$16)*(1+Simulation!I9)/(Simulation!K9-Simulation!I9)/(1+Simulation!K9)^5-Assumptions!$D$17)/Assumptions!$D$18 -> 12.765651 | H9: =IF(D9=1,G9,"") | I9: =IF(D9=0,G9,"") -> 12.765651 | K9: P(value > market price) | L9: =COUNTIF($G$6:$G$2005,">"&Assumptions!$D$19)/L6 -> 0.567 | M9: =COUNTIF($H$6:$H$2005,">"&Assumptions!$D$19)/M6 -> 0.37131631 | N9: =COUNTIF($I$6:$I$2005,">"&Assumptions!$D$19)/N6 -> 0.63380282
